Workbook

Sheet Sheet1
A1: Nome da fonte | B1: Fundidora | C1: Designer | D1: Preço Individual | E1: Preço Completo | F1: Quantidade de Estilos | G1: PreçoMin/Font | H1: Estreia MyFonts | I1: Imagem | J1: Link | K1: Tags | L1: Variable | M1: Lançamentos/Foundrys | N1: Lançamentos/Dia | O1: Lançamentos por Dia
A2: SNS Dear Branch | B2: Sans And Sons | C2: Angga Suwista | D2: R$ 102,15 | E2: R$ 155,91 | F2: 8 | G2: R$ 19,49 | H2: 45972 | I2: imagens\SNS_Dear_Branch.png | J2: https://www.myfonts.com/pt/collections/sns-dear-branch-font-sans-and-sons | K2: Modern Font, Canva Font, Procreate Font, Vintage Font, Serif Font, Signature Font, Groovy Font, Lovely Font, Logo Font, Retro Font, Popular Font, Chic Font, Branding Font, High Fashion, Font Family, Luxury Font, Roman Font, Italian, Handmade, Classic Font | L2: Não | M2: =COUNTIF($B$1:$B$1475, B2) -> 1 | N2: =COUNTIF($H$2:$H$1465, H2) -> 33
A3: MC Kelyber Conieks | B3: Maulana Creative | C3: Gilang Maulana | D3: R$ 59,14 | E3: R$ 59,14 | F3: 1 | G3: R$ 59,14 | H3: 45972 | I3: imagens\MC_Kelyber_Conieks.png | J3: https://www.myfonts.com/pt/collections/mc-kelyber-conieks-font-maulana-creative | K3: Handwritten Font, Signature Script, Elegant Script, Modern Calligraphy, Wedding Font, Branding Font, Luxury Script, Logo Design, Beauty Brand, Fashion Font, Feminine Font, Script Typeface, Hand Drawn, Flowing Script, Stylish Script, Personal Use, Product Label, Signature Style, Elegant Typeface, Natural Script | L3: Não | M3: =COUNTIF($B$1:$B$1475, B3) -> 12 | N3: =COUNTIF($H$2:$H$1465, H3) -> 33
A4: Siren | B4: Sensatype Studio | C4: Zamroni Hamzah | D4: R$ 80,64 | E4: R$ 80,64 | F4: 1 | G4: R$ 80,64 | H4: 45972 | I4: imagens\Siren.png | J4: https://www.myfonts.com/pt/collections/siren-font-sensatype-studio | K4: Luxury Fonts, Luxury Font, Ocean, Sea, Lavish Font, Siren, Luxury, Lavish, Font, Elegant, Branding, Editorial, Sophisticated, Serif, Typography, Stylish, Modern, Classic, Design, Typeface | L4: Não | M4: =COUNTIF($B$1:$B$1475, B4) -> 9 | N4: =COUNTIF($H$2:$H$1465, H4) -> 33
A5: Brasstape | B5: madeDeduk | C5: madededuk | D5: R$ 80,64 | E5: R$ 91,40 | F5: 2 | G5: R$ 45,70 | H5: 45972 | I5: imagens\Brasstape.png | J5: https://www.myfonts.com/pt/collections/brasstape-font-made-deduk | K5: Script, Decorative, Calligraphy, Nostalgic, Vintage Script, Classic Script, Bold Script, Headline Font, Romance Font, Victorian Font, Wedding Font, Curly Font, Swirly Font, Elegant Script, Luxury Font, Christmas Script, Wedding Script, Valentine Script, Nostalgic Font, Fashion Font | L5: Não | M5: =COUNTIF($B$1:$B$1475, B5) -> 7 | N5: =COUNTIF($H$2:$H$1465, H5) -> 33
A6: Royal Ericson | B6: Valorix Studio | C6: Erick Rismawan Valorix | D6: R$ 107,52 | E6: R$ 268,81 | F6: 3 | G6: R$ 89,60 | H6: 45972 | I6: imagens\Royal_Ericson.png | J6: https://www.myfonts.com/pt/collections/royal-ericson-font-valorix-studio | K6: Serif, Modern Serif, Transitional Serif, Luxury Typeface, Branding, Logo, Typetext, Classy Serif, Elegan Serif | L6: Não | M6: =COUNTIF($B$1:$B$1475, B6) -> 2 | N6: =COUNTIF($H$2:$H$1465, H6) -> 33
A7: Fluffy Batter | B7: Stylishtype Studio | C7: Heru Utama Putra | D7: R$ 102,15 | E7: R$ 123,65 | F7: 2 | G7: R$ 61,83 | H7: 45972 | I7: imagens\Fluffy_Batter.png | J7: https://www.myfonts.com/pt/collections/fluffy-batter-font-stylishtype-studio | K7: Brush, Script, Handwritten, Modern, Casual, Stylish, Logo, Branding, Typography, Creative, Food, Organic, Natural, Playful, Lifestyle, Packaging, Menu, Artistic, Design, Font | L7: Não | M7: =COUNTIF($B$1:$B$1475, B7) -> 7 | N7: =COUNTIF($H$2:$H$1465, H7) -> 33
A8: Rexus Cyber | B8: Letterena Studios | C8: Heru Utama Putra | D8: R$ 91,40 | E8: R$ 102,15 | F8: 2 | G8: R$ 51,08 | H8: 45972 | I8: imagens\Rexus_Cyber.png | J8: https://www.myfonts.com/pt/collections/rexus-cyber-font-letterena-studios | K8: Display, Vintage, Bold, Retro, Serif, Rustic, Adventure, Cowboy, Classic, Authentic, Branding, Logo, Typography, Strong, Heritage, Outdoor, Country, Americana, Font, Modern Futuristic Fontype | L8: Não | M8: =COUNTIF($B$1:$B$1475, B8) -> 35 | N8: =COUNTIF($H$2:$H$1465, H8) -> 33
A9: Assallonge | B9: Syafbe | C9: Syafwan Mus | D9: R$ 86,02 | E9: R$ 86,02 | F9: 1 | G9: R$ 86,02 | H9: 45972 | I9: imagens\Assallonge.png | J9: https://www.myfonts.com/pt/collections/assallonge-font-syafbe | K9: Script, Weddingdesigns, Packagingdesign, Digitalart, Graphicdesign, Typelove, Fontinspiration, Natural, Skin Care, Cassual, Valentine, Monoline, Elegant, Handlettering, Handwritten, Handwriting, Invitation, Signature, Product, Logo | L9: Não | M9: =COUNTIF($B$1:$B$1475, B9) -> 2 | N9: =COUNTIF($H$2:$H$1465, H9) -> 33
A10: Seglade | B10: RagamKata | C10: Yogiswhara Dio Prakoso Riadi | D10: R$ 86,02 | E10: R$ 96,77 | F10: 2 | G10: R$ 48,39 | H10: 45972 | I10: imagens\Seglade.png | J10: https://www.myfonts.com/pt/collections/seglade-font-ragamkata | K10: Modern, Sans, Sans Serif, Elegant, Luxury, Branding, Fashion, Wedding, Packaging, Stylish, Clasy, Classic, Versatile, Sophiscated, Minimal, Clean, Beauty, Premium | L10: Não | M10: =COUNTIF($B$1:$B$1475, B10) -> 2 | N10: =COUNTIF($H$2:$H$1465, H10) -> 33
A11: Roseartuk | B11: madeDeduk | C11: madededuk | D11: R$ 80,64 | E11: R$ 91,40 | F11: 2 | G11: R$ 45,70 | H11: 45972 | I11: imagens\Roseartuk.png | J11: https://www.myfonts.com/pt/collections/roseartuk-font-made-deduk | K11: Blackletter, Decorative, Gothic, Oldenglish, Halloween, Rough, Typography, Historical, Vintage, Branding, Deathmetal, Music, Fashion, Headline, Tattoo, Classic Blackletter, Modern Blackletter, Book Cover, Display, Whiskey | L11: Não | M11: =COUNTIF($B$1:$B$1475, B11) -> 7 | N11: =COUNTIF($H$2:$H$1465, H11) -> 33
A12: Salena | B12: Typebae | C12: Iqbal Pauji | D12: R$ 80,64 | E12: R$ 263,43 | F12: 10 | G12: R$ 26,34 | H12: 45972 | I12: imagens\Salena.png | J12: https://www.myfonts.com/pt/collections/salena-font-typebae | K12: Sans, Minimalist, Modern, Clean, Elegant, Display, Futuristic, Logo, Logotype, Branding, Headline, Luxury, Timeless, Magazine, Business, Minimal, Brand Indentity | L12: Não | M12: =COUNTIF($B$1:$B$1475, B12) -> 10 | N12: =COUNTIF($H$2:$H$1465, H12) -> 33
A13: MC Ochlaz | B13: Maulana Creative | C13: Gilang Maulana | D13: R$ 75,27 | E13: R$ 75,27 | F13: 1 | G13: R$ 75,27 | H13: 45972 | I13: imagens\MC_Ochlaz.png | J13: https://www.myfonts.com/pt/collections/mc-ochlaz-font-maulana-creative | K13: Display Font, Serif Typeface, Gothic Style, Horror Movie, Dark Fantasy, Elegant Horror, Vintage Poster, Luxury Branding, Mysterious Font, Halloween Design, Occult Theme, Victorian Era, Classic Look, Modern Gothic, High Contrast, Spooky Text, Headline Font, Title Lettering, Book Cover, Scary Text | L13: Não | M13: =COUNTIF($B$1:$B$1475, B13) -> 12 | N13: =COUNTIF($H$2:$H$1465, H13) -> 33
... A36: Asteza | B36: Genetype | C36: Bagus Arya Kirana | D36: R$ 64,51 | E36: R$ 161,29 | F36: 4 | G36: R$ 40,32 | H36: 45971 | I36: imagens\Asteza.png | J36: https://www.myfonts.com/pt/collections/asteza-font-genetype | K36: Handwritten, Script, Modern, Blur, Hand Drawn, Calligraphy, Cursive, Stylish, Lettering, Smooth, Elegant, Brush, Natural, Restaurant, Logo, Menu, Poster, Signature, Typeface, Handmade | L36: Não | M36: =COUNTIF($B$1:$B$1475, B36) -> 2 | N36: =COUNTIF($H$2:$H$1465, H36) -> 63
A37: TM Mimosa | B37: Tomomi Kanda | C37: Tomomi Kanda | D37: R$ 2.688,09 | E37: R$ 2.688,09 | F37: 3 | G37: R$ 896,03 | H37: 45971 | I37: imagens\TM_Mimosa.png | J37: https://www.myfonts.com/pt/collections/tm-mimosa-font-tomomi-kanda | L37: Não | M37: =COUNTIF($B$1:$B$1475, B37) -> 2 | N37: =COUNTIF($H$2:$H$1465, H37) -> 63
A38: Zyphra | B38: Only Fonts | C38: Olivia Love | D38: R$ 107,52 | E38: R$ 107,52 | F38: 1 | G38: R$ 107,52 | H38: 45971 | I38: imagens\Zyphra.png | J38: https://www.myfonts.com/pt/collections/zyphra-font-only-fonts | K38: Futuristic, Techno, Sci Fi, Cyberpunk, Geometric, Angular, Modern Sans, High Tech, Display, Headline, Logo, Gaming, Esports, Ui Design, Web Hero, Neon, Modular, Alternates, Ligatures, Minimal | L38: Não | M38: =COUNTIF($B$1:$B$1475, B38) -> 10 | N38: =COUNTIF($H$2:$H$1465, H38) -> 63
A39: Qestrafin | B39: Letterena Studios | C39: Heru Utama Putra | D39: R$ 91,40 | E39: R$ 102,15 | F39: 2 | G39: R$ 51,08 | H39: 45971 | I39: imagens\Qestrafin.png | J39: https://www.myfonts.com/pt/collections/qestrafin-font-letterena-studios | K39: Serif Font, Serif, Luxury Serif, Premium Serif, Display Serif, Serif Premium, Branding, Elegant, Font, Modern, Casual, Photography, Visual, Card, Signature, Wedding, Script, Calligraphy, Fashion, Logo | L39: Não | M39: =COUNTIF($B$1:$B$1475, B39) -> 35 | N39: =COUNTIF($H$2:$H$1465, H39) -> 63
A40: Monthe | B40: Rasio Studio | C40: Fajar Indra | D40: R$ 155,91 | E40: R$ 155,91 | F40: 1 | G40: R$ 155,91 | H40: 45971 | I40: imagens\Monthe.png | J40: https://www.myfonts.com/pt/collections/monthe-font-rasio-studio | K40: Monthe, Serif, Calligraphic, Display, Elegant, Luxury, Refined, Stylish, Artistic, Magazine, Modern, Premium, Classy, Sophisticated, Aesthetic, Timeless | L40: Não | M40: =COUNTIF($B$1:$B$1475, B40) -> 17 | N40: =COUNTIF($H$2:$H$1465, H40) -> 63
A41: Lethis | B41: Only Fonts | C41: Olivia Love | D41: R$ 107,52 | E41: R$ 107,52 | F41: 1 | G41: R$ 107,52 | H41: 45971 | I41: imagens\Lethis.png | J41: https://www.myfonts.com/pt/collections/lethis-font-only-fonts | K41: Art Deco, 1920s, Gatsby, Deco Serif, Vintage Luxury, Elegant, Glamour, Fashion, High End, Wedding Invitation, Retro Chic, Editorial, Geometric, Sophisticated, Classy, Jazz Age, Luxury Branding, Ligatures, Multilingual, Stylish | L41: Não | M41: =COUNTIF($B$1:$B$1475, B41) -> 10 | N41: =COUNTIF($H$2:$H$1465, H41) -> 63
A42: Ceyla | B42: Craft Supply Co | C42: Trio Nazzar Saputra | D42: R$ 96,77 | E42: R$ 107,52 | F42: 2 | G42: R$ 53,76 | H42: 45971 | I42: imagens\Ceyla.png | J42: https://www.myfonts.com/pt/collections/ceyla-font-craft-supply-co | K42: Display Serif, Poster, Branding, Logo, Unique, Elegant, Modern, Versatile, Stylish, Album Cover, Typeface, Typography, Font, Design, Fashion | L42: Não | M42: =COUNTIF($B$1:$B$1475, B42) -> 12 | N42: =COUNTIF($H$2:$H$1465, H42) -> 63
A43: Ceyla Unfocus | B43: Craft Supply Co | C43: Trio Nazzar Saputra | D43: R$ 96,77 | E43: R$ 107,52 | F43: 2 | G43: R$ 53,76 | H43: 45971 | I43: imagens\Ceyla_Unfocus.png | J43: https://www.myfonts.com/pt/collections/ceyla-unfocus-font-craft-supply-co | K43: Unfocus, Display, Poster, Branding, Logo, Editorial, Elegant, Versatile, Typeface, Typography, Font, Title | L43: Não | M43: =COUNTIF($B$1:$B$1475, B43) -> 12 | N43: =COUNTIF($H$2:$H$1465, H43) -> 63
A44: Charlen | B44: Amarlettering | C44: Amar Lettering | D44: R$ 80,64 | E44: R$ 80,64 | F44: 1 | G44: R$ 80,64 | H44: 45971 | I44: imagens\Charlen.png | J44: https://www.myfonts.com/pt/collections/charlen-font-amarlettering | K44: Elegant Script, Modern Calligraphy, Handwritten Font, Wedding Font, Signature Style, Feminine Font, Luxury Branding, Stylish Script, Cursive Lettering, Fine Calligraphy, Invitation Font, Delicate Script, Graceful Font, Romantic Typography, Fashion Logo Font, Sophisticated Design, Classy Script, Flowing Handwriting, Chic Typeface, Timeless Elegance | L44: Não | M44: =COUNTIF($B$1:$B$1475, B44) -> 2 | N44: =COUNTIF($H$2:$H$1465, H44) -> 63
A45: BT Annam Neue | B45: BeauType | C45: Duong Nguyen | D45: R$ 241,93 | E45: R$ 2.145,10 | F45: 10 | G45: R$ 214,51 | H45: 45971 | I45: imagens\BT_Annam_Neue.png | J45: https://www.myfonts.com/pt/collections/bt-annam-neue-font-beautype | K45: VietnameseFont, Serif, Cultural, Modern Serif, Heritage Font, SoutheastAsianFont, VintageSerif, DisplaySerif, Royal, Dynasty | L45: Não | M45: =COUNTIF($B$1:$B$1475, B45) -> 2 | N45: =COUNTIF($H$2:$H$1465, H45) -> 63
A46: BT Giusto | B46: Bleifrei Type | C46: Aaron Aebi | D46: R$ 483,86 | E46: R$ 1.612,85 | F46: 7 | G46: R$ 230,41 | H46: 45971 | I46: imagens\BT_Giusto.png | J46: https://www.myfonts.com/pt/collections/bt-giusto-font-bleifrei-type | K46: Sans Serif, Grotesque, Organic Sans, Italian Style, Art Nouveau Inspired, Humanist Sans, Variable Font, Stylistic Alternates, Ligatures, Multilingual Support, Editorial Typeface, Display Use, Clean and Elegant, Contemporary, Neutral yet Warm, Bleifrei Type, Swiss Foundry, 7 Weights, Optical Balance, Modern Grotesk | L46: Sim | M46: =COUNTIF($B$1:$B$1475, B46) -> 2 | N46: =COUNTIF($H$2:$H$1465, H46) -> 63
A47: Eminara | B47: Rasio Studio | C47: Fajar Indra | D47: R$ 155,91 | E47: R$ 155,91 | F47: 1 | G47: R$ 155,91 | H47: 45971 | I47: imagens\Eminara.png | J47: https://www.myfonts.com/pt/collections/eminara-font-rasio-studio | K47: Eminara, Serif, Elegant, Modern, Refined, Classy, Minimal, Timeless, Aesthetic, Stylish, Clean, Professional, Luxury, Display, Magazine | L47: Não | M47: =COUNTIF($B$1:$B$1475, B47) -> 17 | N47: =COUNTIF($H$2:$H$1465, H47) -> 63
A48: Amoura Camorin | B48: Rasio Studio | C48: Fajar Indra | D48: R$ 155,91 | E48: R$ 155,91 | F48: 1 | G48: R$ 155,91 | H48: 45971 | I48: imagens\Amoura_Camorin.png | J48: https://www.myfonts.com/pt/collections/amoura-camorin-font-rasio-studio | K48: Amoura, Camorin, Serif, Condensed, Editorial, Decorative, Elegant, Classic, Modern, Luxury, Fashion, Branding, Vintage, Aesthetic, Artistic, Display, Sophisticated, Chic, Timeless, Classy | L48: Não | M48: =COUNTIF($B$1:$B$1475, B48) -> 17 | N48: =COUNTIF($H$2:$H$1465, H48) -> 63
A49: Avehope | B49: Jafar07 | C49: Bakhrudin Ja'far | D49: R$ 112,90 | E49: R$ 161,29 | F49: 14 | G49: R$ 11,52 | H49: 45971 | I49: imagens\Avehope.png | J49: https://www.myfonts.com/pt/collections/avehope-font-jafar07 | K49: Sans, Geometric, Modern, Clean, Branding, Display, Editorial, Typography, Logo, Typeface, Professional, Minimal, Digital, Design, Font | L49: Não | M49: =COUNTIF($B$1:$B$1475, B49) -> 23 | N49: =COUNTIF($H$2:$H$1465, H49) -> 63
... A80: ATP Lazy House | B80: Typeparties | C80: Thufail Al ghifary | D80: R$ 64,51 | E80: R$ 91,40 | F80: 4 | G80: R$ 22,85 | H80: 45971 | I80: imagens\ATP_Lazy_House.png | J80: https://www.myfonts.com/pt/collections/atp-lazy-house-font-typeparties | K80: Bold Font, Expressive Font, Handwritten Font, Bold Condensed Sans Serif, Rounded Sans Serif Font, Modern Display Font, Industrial Bold Font, Strong Headline Font, Rounded Font, Vintage Industrial Font, Urban Gritty Display Font, Logo Branding Typeface, Bold Rounded Display Font, Music Album Cover Font, Retro Modern Sans Serif, Creative Market Trending Font, High-Impact Bold Font, Headline, Headline Font, Poster Title Font | L80: Não | M80: =COUNTIF($B$1:$B$1475, B80) -> 2 | N80: =COUNTIF($H$2:$H$1465, H80) -> 63
A81: TM Koppe | B81: Tomomi Kanda | C81: Tomomi Kanda | D81: R$ 967,71 | E81: R$ 967,71 | F81: 1 | G81: R$ 967,71 | H81: 45971 | I81: imagens\TM_Koppe.png | J81: https://www.myfonts.com/pt/collections/tm-koppe-font-tomomi-kanda | L81: Não | M81: =COUNTIF($B$1:$B$1475, B81) -> 2 | N81: =COUNTIF($H$2:$H$1465, H81) -> 63
A82: Nubes | B82: Resistenza | C82: Giuseppe Salerno | D82: R$ 209,67 | E82: R$ 263,43 | F82: 2 | G82: R$ 131,72 | H82: 45971 | I82: imagens\Nubes.png | J82: https://www.myfonts.com/pt/collections/nubes-font-resistenza | K82: Handwritten, Casual, Rounded, Friendly, Felt-tip, Soft, Natural, Smooth, Human, Formal, Script, Modern, Personal, Warm, Multilingual, Branding, Packaging, Logo, Greetings Stationary | L82: Não | M82: =COUNTIF($B$1:$B$1475, B82) -> 1 | N82: =COUNTIF($H$2:$H$1465, H82) -> 63
A83: Aero Vault | B83: Sipanji21 | C83: Sipanji | D83: R$ 69,89 | E83: R$ 134,40 | F83: 2 | G83: R$ 67,20 | H83: 45971 | I83: imagens\Aero_Vault.png | J83: https://www.myfonts.com/pt/collections/aero-vault-font-sipanji21 | K83: Graffiti Font, Cyberpunk Font, Tech Font, Futuristic Font, Street Font, Bold Font, Urban Font, Display Font, Gaming Font, Sci-fi Font, Techno Font, Digital Font, Glitch Font, Edgy Font, Creative Font, Robotic Font, Motion Font, Modern Font, Poster Font, Branding Font | L83: Não | M83: =COUNTIF($B$1:$B$1475, B83) -> 5 | N83: =COUNTIF($H$2:$H$1465, H83) -> 63
A84: Elyota Dogla | B84: Ayska | C84: Dhoni Trihatmoko | D84: R$ 112,90 | E84: R$ 112,90 | F84: 1 | G84: R$ 112,90 | H84: 45971 | I84: imagens\Elyota_Dogla.png | J84: https://www.myfonts.com/pt/collections/elyota-dogla-font-ayska | K84: Ideas Font, Script Font, Handwritten Font, Hand Lettered Font, Handwriting Font, Modern, Calligraphy Font, Signature Font, Swashes, Logo Font, Wedding Font, Website Font, Pretty Font, Casual, Chic Font, Ligature, Instagram, Web, Cursive, Elegant | L84: Não | M84: =COUNTIF($B$1:$B$1475, B84) -> 2 | N84: =COUNTIF($H$2:$H$1465, H84) -> 63
A85: Caples | B85: Drizy Font | C85: Panca Ahmadi Hasan | D85: R$ 138,60 | E85: R$ 138,60 | F85: 1 | G85: R$ 138,60 | H85: 45971 | I85: imagens\Caples.png | J85: https://www.myfonts.com/pt/collections/caples-font-drizy-font | K85: Display, High Contrast, Reverse Contrast, Expanded, Rounded, Bubbly, Y2k, Modern, Futuristic | L85: Não | M85: =COUNTIF($B$1:$B$1475, B85) -> 2 | N85: =COUNTIF($H$2:$H$1465, H85) -> 63
A86: Thio Filmen | B86: Twinletter | C86: Rozikan Rozikan | D86: R$ 134,40 | E86: R$ 134,40 | F86: 1 | G86: R$ 134,40 | H86: 45971 | I86: imagens\Thio_Filmen.png | J86: https://www.myfonts.com/pt/collections/thio-filmen-font-twinletter | K86: Display, Action, Cartoon, Hero, Movie, Headline, Poster, Typography, Cinema, Film, Entertaiment, Bold, Modern, Premium, Creative, Branding, Show, Expressive, Dynamic, Title | L86: Não | M86: =COUNTIF($B$1:$B$1475, B86) -> 2 | N86: =COUNTIF($H$2:$H$1465, H86) -> 63
A87: Under Mind Sans | B87: Multype Studio | C87: Mulia Yanto | D87: R$ 134,40 | E87: R$ 182,79 | F87: 4 | G87: R$ 45,70 | H87: 45971 | I87: imagens\Under_Mind_Sans.png | J87: https://www.myfonts.com/pt/collections/under-mind-sans-font-multype-studio | K87: Under Mind Font, Sport Font, Racing Font, Bold Display Typeface, Modern Sans Serif, Athletic Typography, Esports Logo Font, Geometric Sans Font, Performance Typeface, Futuristic Font, Strong Display Font, Tech Font, Racing Logo Typeface, Modern Bold Typography, Energy Font, Dynamic Font, Motorsport Font, Headline Font, Power Display Font, All Caps Font | L87: Não | M87: =COUNTIF($B$1:$B$1475, B87) -> 3 | N87: =COUNTIF($H$2:$H$1465, H87) -> 63
A88: Lova Bold | B88: Nirmana Visual | C88: Sigit Dwipa | D88: R$ 129,03 | E88: R$ 129,03 | F88: 2 | G88: R$ 64,52 | H88: 45971 | I88: imagens\Lova_Bold.png | J88: https://www.myfonts.com/pt/collections/lova-bold-font-nirmana-visual | K88: Bold, Extrude, Playful, Logo, Branding, Poster, Retro, Food, Cafe, Menu, Quote, Ligature, Business Cards, Display | L88: Não | M88: =COUNTIF($B$1:$B$1475, B88) -> 7 | N88: =COUNTIF($H$2:$H$1465, H88) -> 63
A89: Orenza Bold | B89: Nirmana Visual | C89: Sigit Dwipa | D89: R$ 129,03 | E89: R$ 129,03 | F89: 2 | G89: R$ 64,52 | H89: 45971 | I89: imagens\Orenza_Bold.png | J89: https://www.myfonts.com/pt/collections/orenza-bold-font-nirmana-visual | K89: Bold, Modern, Professional, Corporate, Logo, Clean, Strong, Website, Headlines, Business, Branding, Elegance | L89: Não | M89: =COUNTIF($B$1:$B$1475, B89) -> 7 | N89: =COUNTIF($H$2:$H$1465, H89) -> 63
A90: Chalen | B90: Craft Supply Co | C90: Trio Nazzar Saputra | D90: R$ 96,77 | E90: R$ 107,52 | F90: 2 | G90: R$ 53,76 | H90: 45971 | I90: imagens\Chalen.png | J90: https://www.myfonts.com/pt/collections/chalen-font-craft-supply-co | K90: Playful, Bold, Poster, Headline, Title, Cheerful, Typeface, Typography, Font, Eye Catching, Bubble, Fun, Childish, Kids, Joyful, Fashion | L90: Não | M90: =COUNTIF($B$1:$B$1475, B90) -> 12 | N90: =COUNTIF($H$2:$H$1465, H90) -> 63
A91: Greathem | B91: Nian Keun Studio | C91: Mugi Raharjo | D91: R$ 75,27 | E91: R$ 75,27 | F91: 1 | G91: R$ 75,27 | H91: 45971 | I91: imagens\Greathem.png | J91: https://www.myfonts.com/pt/collections/greathem-font-nian-keun-studio | K91: Experimental, Display, Tall Narraw, Minimalist Brutalist, Headline, Tittle, Impactful, Unique, Contrast, High, Condensed | L91: Não | M91: =COUNTIF($B$1:$B$1475, B91) -> 1 | N91: =COUNTIF($H$2:$H$1465, H91) -> 63
A92: Cidway | B92: Drizy Font | C92: Panca Ahmadi Hasan | D92: R$ 138,60 | E92: R$ 138,60 | F92: 1 | G92: R$ 138,60 | H92: 45971 | I92: imagens\Cidway.png | J92: https://www.myfonts.com/pt/collections/cidway-font-drizy-font | K92: Display, Rounded, Slanted, Y2k, Bold, Condensed, Bubbly, Modern | L92: Não | M92: =COUNTIF($B$1:$B$1475, B92) -> 2 | N92: =COUNTIF($H$2:$H$1465, H92) -> 63
...

Sheet Semana
A1: dom | B1: seg | C1: ter | D1: qua | E1: qui | F1: sex | G1: sab | I1: dom | J1: seg | K1: ter | L1: qua | M1: qui | N1: sex | O1: sab
D2: 45959 | E2: 45960 | F2: 45961 | G2: 45962 | O2: 45962
D3: =SUMIF(Tabela1[Estreia MyFonts],D2,Tabela1[Quantidade de Estilos]) -> 0 | E3: =SUMIF(Tabela1[Estreia MyFonts],E2,Tabela1[Quantidade de Estilos]) -> 0 | F3: =SUMIF(Tabela1[Estreia MyFonts],F2,Tabela1[Quantidade de Estilos]) -> 0 | G3: =SUMIF(Tabela1[Estreia MyFonts],G2,Tabela1[Quantidade de Estilos]) -> 113 | O3: =COUNTIF(Tabela1[Estreia MyFonts], O2) -> 12
A4: 45963 | B4: 45964 | C4: 45965 | D4: 45966 | E4: 45967 | F4: 45968 | G4: 45969 | I4: 45963 | J4: 45964 | K4: 45965 | L4: 45966 | M4: 45967 | N4: 45968 | O4: 45969
A5: =SUMIF(Tabela1[Estreia MyFonts],A4,Tabela1[Quantidade de Estilos]) -> 7 | B5: =SUMIF(Tabela1[Estreia MyFonts],B4,Tabela1[Quantidade de Estilos]) -> 139 | C5: =SUMIF(Tabela1[Estreia MyFonts],C4,Tabela1[Quantidade de Estilos]) -> 26 | D5: =SUMIF(Tabela1[Estreia MyFonts],D4,Tabela1[Quantidade de Estilos]) -> 91 | E5: =SUMIF(Tabela1[Estreia MyFonts],E4,Tabela1[Quantidade de Estilos]) -> 136 | F5: =SUMIF(Tabela1[Estreia MyFonts],F4,Tabela1[Quantidade de Estilos]) -> 87 | G5: =SUMIF(Tabela1[Estreia MyFonts],G4,Tabela1[Quantidade de Estilos]) -> 0 | I5: =COUNTIF(Tabela1[Estreia MyFonts], I4) -> 2 | J5: =COUNTIF(Tabela1[Estreia MyFonts], J4) -> 23 | K5: =COUNTIF(Tabela1[Estreia MyFonts], K4) -> 16 | L5: =COUNTIF(Tabela1[Estreia MyFonts], L4) -> 40 | M5: =COUNTIF(Tabela1[Estreia MyFonts], M4) -> 51 | N5: =COUNTIF(Tabela1[Estreia MyFonts], N4) -> 36 | O5: =COUNTIF(Tabela1[Estreia MyFonts], O4) -> 0
A6: 45970 | B6: 45971 | C6: 45972 | D6: 45973 | E6: 45974 | F6: 45975 | G6: 45976 | I6: 45970 | J6: 45971 | K6: 45972 | L6: 45973 | M6: 45974 | N6: 45975 | O6: 45976
A7: =SUMIF(Tabela1[Estreia MyFonts],A6,Tabela1[Quantidade de Estilos]) -> 0 | B7: =SUMIF(Tabela1[Estreia MyFonts],B6,Tabela1[Quantidade de Estilos]) -> 162 | C7: =SUMIF(Tabela1[Estreia MyFonts],C6,Tabela1[Quantidade de Estilos]) -> 108 | D7: =SUMIF(Tabela1[Estreia MyFonts],D6,Tabela1[Quantidade de Estilos]) -> 5 | E7: =SUMIF(Tabela1[Estreia MyFonts],E6,Tabela1[Quantidade de Estilos]) -> 150 | F7: =SUMIF(Tabela1[Estreia MyFonts],F6,Tabela1[Quantidade de Estilos]) -> 170 | G7: =SUMIF(Tabela1[Estreia MyFonts],G6,Tabela1[Quantidade de Estilos]) -> 0 | I7: =COUNTIF(Tabela1[Estreia MyFonts], I6) -> 0 | J7: =COUNTIF(Tabela1[Estreia MyFonts], J6) -> 63 | K7: =COUNTIF(Tabela1[Estreia MyFonts], K6) -> 33 | L7: =COUNTIF(Tabela1[Estreia MyFonts], L6) -> 3 | M7: =COUNTIF(Tabela1[Estreia MyFonts], M6) -> 36 | N7: =COUNTIF(Tabela1[Estreia MyFonts], N6) -> 19 | O7: =COUNTIF(Tabela1[Estreia MyFonts], O6) -> 0
A8: 45977 | B8: 45978 | C8: 45979 | D8: 45980 | E8: 45981 | F8: 45982 | G8: 45983 | I8: 45977 | J8: 45978 | K8: 45979 | L8: 45980 | M8: 45981 | N8: 45982 | O8: 45983
A9: =SUMIF(Tabela1[Estreia MyFonts],A8,Tabela1[Quantidade de Estilos]) -> 0 | B9: =SUMIF(Tabela1[Estreia MyFonts],B8,Tabela1[Quantidade de Estilos]) -> 0 | C9: =SUMIF(Tabela1[Estreia MyFonts],C8,Tabela1[Quantidade de Estilos]) -> 62 | D9: =SUMIF(Tabela1[Estreia MyFonts],D8,Tabela1[Quantidade de Estilos]) -> 76 | E9: =SUMIF(Tabela1[Estreia MyFonts],E8,Tabela1[Quantidade de Estilos]) -> 245 | F9: =SUMIF(Tabela1[Estreia MyFonts],F8,Tabela1[Quantidade de Estilos]) -> 287 | G9: =SUMIF(Tabela1[Estreia MyFonts],G8,Tabela1[Quantidade de Estilos]) -> 2 | I9: =COUNTIF(Tabela1[Estreia MyFonts], I8) -> 0 | J9: =COUNTIF(Tabela1[Estreia MyFonts], J8) -> 0 | K9: =COUNTIF(Tabela1[Estreia MyFonts], K8) -> 10 | L9: =COUNTIF(Tabela1[Estreia MyFonts], L8) -> 28 | M9: =COUNTIF(Tabela1[Estreia MyFonts], M8) -> 70 | N9: =COUNTIF(Tabela1[Estreia MyFonts], N8) -> 58 | O9: =COUNTIF(Tabela1[Estreia MyFonts], O8) -> 1
A10: 45984 | B10: 45985 | C10: 45986 | D10: 45987 | E10: 45988 | F10: 45989 | I10: 45984 | J10: 45985 | K10: 45986 | L10: 45987 | M10: 45988 | N10: 45989
A11: =SUMIF(Tabela1[Estreia MyFonts],A10,Tabela1[Quantidade de Estilos]) -> 0 | B11: =SUMIF(Tabela1[Estreia MyFonts],B10,Tabela1[Quantidade de Estilos]) -> 41 | C11: =SUMIF(Tabela1[Estreia MyFonts],C10,Tabela1[Quantidade de Estilos]) -> 286 | D11: =SUMIF(Tabela1[Imagem],D10,Tabela1[PreçoMin/Font]) -> 0 | E11: =SUMIF(Tabela1[Link],E10,Tabela1[Estreia MyFonts]) -> 0 | F11: =SUMIF(Tabela1[Tags],F10,Tabela1[Imagem]) -> 0 | I11: =COUNTIF(Tabela1[Estreia MyFonts], I10) -> 0 | J11: =COUNTIF(Tabela1[Estreia MyFonts], J10) -> 11 | K11: =COUNTIF(Tabela1[Estreia MyFonts], K10) -> 27 | L11: =COUNTIF(Tabela1[Estreia MyFonts], L10) -> 1 | M11: =COUNTIF(Tabela1[Estreia MyFonts], M10) -> 73 | N11: =COUNTIF(Tabela1[Estreia MyFonts], N10) -> 0
A13: =AVERAGE(A3,A5,A7,A9,A11) -> 1.75 | B13: =AVERAGE(B3,B5,B7,B9,B11) -> 85.5 | C13: =AVERAGE(C3,C5,C7,C9,C11) -> 120.5 | D13: =AVERAGE(D3,D5,D7,D9,D11) -> 34.4 | E13: =AVERAGE(E3,E5,E7,E9,E11) -> 106.2 | F13: =AVERAGE(F3,F5,F7,F9,F11) -> 108.8 | G13: =AVERAGE(G3,G5,G7,G9,G11) -> 28.75 | I13: =AVERAGE(I3,I5,I7,I9,I11) -> 0.5 | J13: =AVERAGE(J3,J5,J7) -> 43 | K13: =AVERAGE(K3,K5,K7) -> 24.5 | L13: =AVERAGE(L3,L5,L7) -> 21.5 | M13: =AVERAGE(M3,M5,M7) -> 43.5 | N13: =AVERAGE(N3,N5,N7) -> 27.5 | O13: =AVERAGE(O3,O5,O7,O9,O11) -> 3.25 | P13: =AVERAGE(J13:N13) -> 32

Sheet Resultados
A1: Mais Cara% | B1: Quem lançou Mais* | C1: Mais Pesos | D1: Média de pesos | E1: Dia com + Lançamentos | G1: Mais Cara% | H1: Quem lançou Mais* | I1: Mais Pesos | J1: Média de pesos | K1: Dia com + Lançamentos
A2: =MAX(Sheet1!$G$2:$G$1351)/$A$5 -> #VALUE! | B2: =MAX(Sheet1!$M$2:$M$1351) -> 43 | C2: =MAX(Sheet1!$F2:$F1351) -> 141 | D2: =AVERAGE(Sheet1!$F2:$F1339) -> 4.2263844 | E2: =MAX(Sheet1!$N$2:$N$1351) -> 73 | G2: =MAX(Sheet1!$G$2:$G$1351)/$A$5 -> #VALUE! | H2: =MAX(Sheet1!$M$2:$M$1351) -> 43 | I2: =MAX(Sheet1!$F2:$F1351) -> 141 | J2: =AVERAGE(Sheet1!$F2:$F1339) -> 4.2263844 | K2: =MAX(Sheet1!$N$2:$N$1351) -> 73
A3: Mais Barata% | B3: $ + Barata/Ind | C3: Média de % | D3: Média de $ Ind | E3: Dia com - Lançamentos | G3: Mais Barata% | H3: $ + Barata/Ind | I3: Média de % | J3: Média de $ Ind | K3: Dia com - Lançamentos
A4: =MIN(Sheet1!E2:E1465)/$A$5 -> 9.1899441 | B4: =MIN(Sheet1!D2:D1465)/$A$5 -> 0.30540037 | C4: =AVERAGE(Sheet1!$G$2:$G$1351)/$A$5 -> #VALUE! | D4: =AVERAGE(Sheet1!D2:D1351)/$A$5 -> 27.139956 | E4: =MIN(Sheet1!$N$2:$N$1351) -> 1 | G4: =MIN(Sheet1!K2:K1465)/$A$5 -> 0 | H4: =MIN(Sheet1!J2:J1465)/$A$5 -> 0 | I4: =AVERAGE(Sheet1!$G$2:$G$1351)/$A$5 -> #VALUE! | J4: =AVERAGE(Sheet1!J2:J1351)/$A$5 -> #DIV/0! | K4: =MIN(Sheet1!$N$2:$N$1351) -> 1
A5: 5.37 | B5: Dolar Hoje | G5: 5.3 | H5: Dolar Hoje
A7: $ + caro/Ind | B7: Pacote + Barato | C7: Pacote + Caro | D7: Média de Pacotes | E7: Média de Lançamentos | G7: $ + caro/Ind | H7: Pacote + Barato | I7: Pacote + Caro | J7: Média de Pacotes | K7: Média de Lançamentos
A8: =MAX(Sheet1!$D$2:$D1404)/$A$5 -> 326.72439 | B8: =MIN(Sheet1!E1:E1339)/$A$5 -> 9.1899441 | C8: =MAX(Sheet1!$E$2:$E$1465)/$A$5 -> 599.24209 | D8: =AVERAGE(Sheet1!$E$2:$E$1351)/$A$5 -> 52.504557 | E8: =AVERAGE(Sheet1!$N$2:$N$1351) -> 46.390879 | G8: =MAX(Sheet1!$D$2:$D1404)/$A$5 -> 326.72439 | H8: =MIN(Sheet1!K1:K1339)/$A$5 -> 0 | I8: =MAX(Sheet1!$E$2:$E$1465)/$A$5 -> 599.24209 | J8: =AVERAGE(Sheet1!$E$2:$E$1351)/$A$5 -> 52.504557 | K8: =AVERAGE(Sheet1!$N$2:$N$1351) -> 46.390879
A12: A fonte com o maior Melhor Valor Por Estilo é | B12: {=_xlfn.XLOOKUP(A2*A5,Sheet1!$G$2:$G$1351,Sheet1!$A$2:$A$1351,Sem Nome, -1,1)} -> #VALUE! | C12: , e custa | D12: $ | E12: =TEXT(A2, "0.00") -> #VALUE! | F12: . | G12: A fonte com o maior Melhor Valor Por Estilo é | H12: {=_xlfn.XLOOKUP(G2*G5,Sheet1!$G$2:$G$1351,Sheet1!$A$2:$A$1351,Sem Nome, -1,1)} -> #VALUE! | I12: , e custa | J12: $ | K12: =TEXT(G2, "0.00") -> #VALUE!
A13: A fonte com o menor Melhor Valor Por Estilo é | B13: {=_xlfn.XLOOKUP(A4*$A$5,Sheet1!$G$2:$G$1351,Sheet1!$A$2:$A$1351,Sem Nome, 0,1)} -> Faboulus Tintonya | C13: , e custa | D13: $ | E13: =TEXT(A4, "0.00") -> 9.19 | F13: . | G13: A fonte com o menor Melhor Valor Por Estilo é | H13: {=_xlfn.XLOOKUP(G4*$A$5,Sheet1!$G$2:$G$1351,Sheet1!$A$2:$A$1351,Sem Nome, 0,1)} -> #NAME? | I13: , e custa | J13: $ | K13: =TEXT(G4, "0.00") -> 0.00
A14: A média de melhor valor comprando em pacote é | B14: $ | C14: =TEXT(C4, "0.00") -> #VALUE! | D14: . | G14: A média de melhor valor comprando em pacote é | H14: $ | I14: =TEXT(I4, "0.00") -> #VALUE! | J14: .
A16: A fundidora que lançou mais fontes foi a | B16: {=_xlfn.XLOOKUP(D16,Sheet1!$N$2:$N$1351,Sheet1!$B$2:$B$1351,Sem Nome, -1,1)} -> Letterena Studios | C16: com o total de | D16: =B2 -> 43 | E16: fontes lançadas. | G16: A fundidora que lançou mais fontes foi a | H16: {=_xlfn.XLOOKUP(J16,Sheet1!$N$2:$N$1351,Sheet1!$B$2:$B$1351,Sem Nome, -1,1)} -> Letterena Studios | I16: com o total de | J16: =H2 -> 43 | K16: fontes lançadas.
A17: {=_xlfn.XLOOKUP(D17,Sheet1!$F$2:$F$1351,Sheet1!$A$2:$A$1351,Sem Nome, 0,1)} -> Velion | B17: É a fonte com o maior número de estilos | C17: com o total de | D17: =C2 -> 141 | E17: estilos lançados. | G17: {=_xlfn.XLOOKUP(J17,Sheet1!$F$2:$F$1351,Sheet1!$A$2:$A$1351,Sem Nome, 0,1)} -> Velion | H17: É a fonte com o maior número de estilos | I17: com o total de | J17: =I2 -> 141 | K17: estilos lançados.
A18: Superando a média de | B18: $ | C18: =TEXT(D2, "0.00") -> 4.23 | D18: por fonte no geral. | G18: Superando a média de | H18: $ | I18: =TEXT(J2, "0.00") -> 4.23 | J18: por fonte no geral.
A20: O dia com mais lançamentos consecutivos teve | B20: =E2 -> 73 | C20: fontes lançadas | D20: a média é de | F20: =TEXT(E8, "0.00") -> 46.39 | G20: O dia com mais lançamentos consecutivos teve | H20: =K2 -> 73 | I20: fontes lançadas | J20: a média é de
A22: Ainda sobre preços o pacote mais caro custa | B22: $ | C22: =TEXT(C8, "0.00") -> 599.24 | D22: e se chama | E22: {=_xlfn.XLOOKUP(C22*$A$5,Sheet1!$E$2:$E$1351,Sheet1!$A$2:$A$1351,Sem Nome, -1,1)} -> BT Circuit | F22: com | G22: Ainda sobre preços o pacote mais caro custa | H22: $ | I22: =TEXT(I8, "0.00") -> 599.24 | J22: e se chama | K22: {=_xlfn.XLOOKUP(I22*$A$5,Sheet1!$E$2:$E$1351,Sheet1!$A$2:$A$1351,Sem Nome, -1,1)} -> BT Circuit
A24: O pacote com o menor preço custa | B24: $ | C24: =TEXT(B8,"0.00") -> 9.19 | D24: e se chama | E24: {=_xlfn.XLOOKUP(C26*$A$5,Sheet1!$E$2:$E$1351,Sheet1!$A$2:$A$1351,Sem Nome, -1,-1)} -> Myrak | F24: com | G24: O pacote com o menor preço custa | H24: $ | I24: =TEXT(H8,"0.00") -> 0.00 | J24: e se chama | K24: {=_xlfn.XLOOKUP(I26*$A$5,Sheet1!$E$2:$E$1351,Sheet1!$A$2:$A$1351,Sem Nome, -1,-1)} -> Myrak
A26: O peso individual mais barato custa | B26: $ | C26: =TEXT(B2, "0.00") -> 43.00 | D26: e se chama | E26: {=_xlfn.XLOOKUP(C26*$A$5,Sheet1!$D$2:$D$1351,Sheet1!$A$2:$A$1351,Sem Nome, -1,-1)} -> Ethere S VF | F26: . | G26: O peso individual mais barato custa | H26: $ | I26: =TEXT(H2, "0.00") -> 43.00 | J26: e se chama | K26: {=_xlfn.XLOOKUP(I26*$A$5,Sheet1!$D$2:$D$1351,Sheet1!$A$2:$A$1351,Sem Nome, -1,-1)} -> Ethere S VF
A28: =_xlfn.CONCAT(A12,B12,C12,D12,E12,F12,G12, H12, I12,J12) -> #VALUE! | G28: =_xlfn.CONCAT(G12,H12,I12,J12,K12,L12,M12, N12, O12,P12) -> #VALUE!
A29: =_xlfn.CONCAT(A13,B13,C13,D13,E13,F13,G13, H13, I13,J13) -> #NAME? | G29: =_xlfn.CONCAT(G13,H13,I13,J13,K13,L13,M13, N13, O13,P13) -> #NAME?
A30: =_xlfn.CONCAT(A14,B14,C14,D14,E14,F14,G14, H14, I14,J14) -> #VALUE! | G30: =_xlfn.CONCAT(G14,H14,I14,J14,K14,L14,M14, N14, O14,P14) -> #VALUE!
A32: =_xlfn.CONCAT(A16,B16,C16,D16,E16,F16,G16, H16, I16,J16) -> A fundidora que lançou mais fontes foi a Letterena Studios com o total de 43 fontes lançadas.A fundidora que lançou mais fontes foi a Letterena Studios com o total de 43 | G32: =_xlfn.CONCAT(G16,H16,I16,J16,K16,L16,M16, N16, O16,P16) -> A fundidora que lançou mais fontes foi a Letterena Studios com o total de 43 fontes lançadas.
A33: =_xlfn.CONCAT(A17,B17,C17,D17,E17,F17,G17, H17, I17,J17) -> Velion É a fonte com o maior número de estilos com o total de 141 estilos lançados.Velion É a fonte com o maior número de estilos com o total de 141 | G33: =_xlfn.CONCAT(G17,H17,I17,J17,K17,L17,M17, N17, O17,P17) -> Velion É a fonte com o maior número de estilos com o total de 141 estilos lançados.
A34: =_xlfn.CONCAT(A18,B18,C18,D18,E18,F18,G18, H18, I18,J18) -> Superando a média de $ 4.23 por fonte no geral.Superando a média de $ 4.23 por fonte no geral. | G34: =_xlfn.CONCAT(G18,H18,I18,J18,K18,L18,M18, N18, O18,P18) -> Superando a média de $ 4.23 por fonte no geral.
A36: =_xlfn.CONCAT(A20,B20,C20,D20,E20,F20,G20, H20, I20,J20) -> O dia com mais lançamentos consecutivos teve 73 fontes lançadas a média é de 46.39O dia com mais lançamentos consecutivos teve 73 fontes lançadas a média é de | G36: =_xlfn.CONCAT(G20,H20,I20,J20,K20,L20,M20, N20, O20,P20) -> O dia com mais lançamentos consecutivos teve 73 fontes lançadas a média é de
A37: =_xlfn.CONCAT(A21,B21,C21,D21,E21,F21,G21, H21, I21,J21) | G37: =_xlfn.CONCAT(G21,H21,I21,J21,K21,L21,M21, N21, O21,P21)
A38: =_xlfn.CONCAT(A22,B22,C22,D22,E22,F22,G22, H22, I22,J22) -> Ainda sobre preços o pacote mais caro custa $ 599.24e se chama BT Circuit com Ainda sobre preços o pacote mais caro custa $ 599.24e se chama | G38: =_xlfn.CONCAT(G22,H22,I22,J22,K22,L22,M22, N22, O22,P22) -> Ainda sobre preços o pacote mais caro custa $ 599.24e se chama BT Circuit
A39: =_xlfn.CONCAT(A23,B23,C23,D23,E23,F23,G23, H23, I23,J23) | G39: =_xlfn.CONCAT(G23,H23,I23,J23,K23,L23,M23, N23, O23,P23)
A40: =_xlfn.CONCAT(A24,B24,C24,D24,E24,F24,G24, H24, I24,J24) -> O pacote com o menor preço custa $ 9.19 e se chama Myrak com O pacote com o menor preço custa $ 0.00 e se chama | G40: =_xlfn.CONCAT(G24,H24,I24,J24,K24,L24,M24, N24, O24,P24) -> O pacote com o menor preço custa $ 0.00 e se chama Myrak
A41: =_xlfn.CONCAT(A25,B25,C25,D25,E25,F25,G25, H25, I25,J25) | G41: =_xlfn.CONCAT(G25,H25,I25,J25,K25,L25,M25, N25, O25,P25)
A42: =_xlfn.CONCAT(A26,B26,C26,D26,E26,F26) -> O peso individual mais barato custa $ 43.00 e se chama Ethere S VF. | G42: =_xlfn.CONCAT(G26,H26,I26,J26,K26,L26) -> O peso individual mais barato custa $ 43.00 e se chama Ethere S VF
A44: =_xlfn.CONCAT(G26,H26,J26,I26,K26) -> O peso individual mais barato custa $ e se chama 43.00Ethere S VF | G44: =_xlfn.CONCAT(M26,N26,P26,O26,Q26)
